<?xml version='1.0'?>
 
<robot name="Robot_description" xmlns:xacro="http://www.ros.org/wiki/xacro">

  <xacro:include filename="$(find Robot_description)/urdf/Robot_description.gazebo" />

  <link name='base_footprint'>
    <pose>0 0 0 0 0 0</pose>
 
    <inertial>
      <mass value="15.0"/>
      <origin xyz="0 0 0.05" rpy=" 0 0 0"/>
      <inertia
          ixx="0.1" ixy="0" ixz="0"
          iyy="0.1" iyz="0"
          izz="0.1"
      />
    </inertial>
 
    <collision name='collision'>
      <origin xyz="0 0 0.05" rpy=" 0 0 0"/> 
      <geometry>
        <box size=".4 .3 .05"/>
      </geometry>
    </collision>
 
    <visual name='chassis_visual'>
      <origin xyz="0 0 0.05" rpy=" 0 0 0"/>
      <geometry>
        <box size=".4 .3 .05"/>
      </geometry>
    </visual>
 
    <collision name='caster_collision'>
      <origin xyz="0.15 0 0.03" rpy=" 0 0 0"/>
      <geometry>
        <sphere radius="0.03"/>
      </geometry>
    </collision>
 
    <visual name='caster_visual'>
      <origin xyz="0.15 0 0.03" rpy=" 0 0 0"/>
      <geometry>
        <sphere radius="0.03"/>
      </geometry>
    </visual>

  </link>

  <!-- Add link left Wheel --> 
  <link name='left_wheel'>
     <inertial>
      <mass value="5"/>
      <origin xyz="-0.05 0 0.015" rpy=" 0 1.5707 1.5707"/>
      <inertia
	  ixx="0.1" ixy="0" ixz="0"
	  iyy="0.1" iyz="0"
	  izz="0.1"
      />
     </inertial>

     <collision>
      <origin xyz="-0.05 0 0.015" rpy=" 0 1.5707 1.5707"/>
      <geometry>
	<cylinder radius="0.0325" length="0.03"/>
      </geometry>
     </collision>

     <visual>
      <origin xyz="-0.05 0 0.015" rpy=" 0 1.5707 1.5707"/>
      <geometry>
	<cylinder radius="0.0325" length="0.03"/>
      </geometry>
     </visual>
  </link>

  <!-- Add link right Wheel --> 
  <link name='right_wheel'>
     <inertial>
      <mass value="5"/>
      <origin xyz="-0.05 0 0.015" rpy=" 0 1.5707 1.5707"/>
      <inertia
	  ixx="0.1" ixy="0" ixz="0"
	  iyy="0.1" iyz="0"
	  izz="0.1"
      />
     </inertial>

     <collision>
      <origin xyz="-0.05 0 0.015" rpy=" 0 1.5707 1.5707"/>
      <geometry>
	<cylinder radius="0.0325" length="0.03"/>
      </geometry>
     </collision>

     <visual>
      <origin xyz="-0.05 0 0.015" rpy=" 0 1.5707 1.5707"/>
      <geometry>
	<cylinder radius="0.0325" length="0.03"/>
      </geometry>
     </visual>
  </link>

  <!-- Add joint left wheel --> 
  <joint type="continuous" name="left_wheel_hinge">

    <origin xyz="-0.05 0.15 0.015" rpy="0 0 0"/>

    <child link="left_wheel"/>

    <parent link="base_footprint"/>

    <axis xyz="0 1 0" rpy="0 0 0"/>

    <limit effort="10000" velocity="1000"/>

    <dynamics damping="1.0" friction="1.0"/>

  </joint>

  <!-- Add joint right wheel --> 
  <joint type="continuous" name="right_wheel_hinge">

    <origin xyz="-0.05 -0.15 0.015" rpy="0 0 0"/>

    <child link="right_wheel"/>

    <parent link="base_footprint"/>

    <axis xyz="0 1 0" rpy="0 0 0"/>

    <limit effort="10000" velocity="1000"/>

    <dynamics damping="1.0" friction="1.0"/>

  </joint>


  <!--kinect joint /-->

  <joint name="kinect_joint" type="fixed">

    <origin xyz="0.12 0 .05" rpy="0 0 0"/>

    <parent link="base_footprint"/>
    <child link="camera_link"/>

  </joint>


  <!--Kinect  Link /-->

  <link name="camera_link">
    
  <visual>

      <origin xyz="0 0 0.05" rpy="0 0 0"/>

      <geometry>

      <mesh filename="package://Robot_description/meshes/kinect.dae"/>

      </geometry>

   </visual>
    

   <collision>
    <origin xyz="0 0 0" rpy="0 0 0"/>

    <geometry>
    <box size="0.1 0.1 0.1"/>
    </geometry>
    
   </collision>

   <inertial>
     <mass value="1e-5" />
     <origin xyz="0 0 0" rpy="0 0 0"/>
     <inertia ixx="1e-6" ixy="0" ixz="0" iyy="1e-6" iyz="0" izz="1e-6" />
   </inertial>
  </link>

  <!--  Kinect Optical Link and joints   /-->

  <joint name="kinect_optical_joint" type="fixed">

    <origin xyz="0 0 0" rpy="-1.5707 0 -1.5707"/> <!-- To invert the coordinates from image convention (Z is forward) to normal xyz /-->
    <parent link="camera_link"/>
    <child link="kinect_optical"/>
  </joint>

  <!--Virtual link to project the images to, and then flip it to us as its joint is flipped  /-->
  <link name="kinect_optical">
  </link>

</robot>
